..EEEE
======================================================================
ERROR: test_list_int (__main__.Test03_ModifyContact)
*** Test03 *** GIVEN: filename t99.dat = {'7145551111': ['Steve', 'Jobs'], '5625553333': ['Bill', 'Gates']} AND contacts = Contacts(filename='t99.dat') *** FUNCTION CALL: contacts.modify_contact(id = '7145551111', first_name = 'Richard', last_name = 'Stallman') *** EXPECT: filename t99.dat = {'5625553333': ['Bill', 'Gates'], '7145551111': ['Richard', 'Stallman']} ***
----------------------------------------------------------------------
Traceback (most recent call last):
  File "/home/elithomas/Documents/CPSC223P/CPSC223P-Lab7/test.py", line 50, in test_list_int
    r = contacts.modify_contact(id = '7145551111', first_name = 'Richard', last_name = 'Stallman')
AttributeError: 'Contacts' object has no attribute 'modify_contact'

======================================================================
ERROR: test_list_int (__main__.Test04_ModifyContact)
*** Test04 *** GIVEN: filename t99.dat = {'7145551111': ['Steve', 'Jobs'], '5625553333': ['Bill', 'Gates']} AND contacts = Contacts(filename='t99.dat') *** FUNCTION CALL: r = contacts.modify_contact(id = '7145559999', first_name = 'Richard', last_name = 'Stallman') *** EXPECT: r = 'error' ***
----------------------------------------------------------------------
Traceback (most recent call last):
  File "/home/elithomas/Documents/CPSC223P/CPSC223P-Lab7/test.py", line 66, in test_list_int
    r = contacts.modify_contact(id = '7145559999', first_name = 'Richard', last_name = 'Stallman')
AttributeError: 'Contacts' object has no attribute 'modify_contact'

======================================================================
ERROR: test_list_int (__main__.Test05_DeleteContact)
*** Test05 *** GIVEN: filename t99.dat = {'7145551111': ['Steve', 'Jobs'], '5625553333': ['Bill', 'Gates']} AND contacts = Contacts(filename='t99.dat') *** FUNCTION CALL: contacts.delete_contact(id = '7145551111') *** EXPECT: filename t99.dat = {'5625553333': ['Bill', 'Gates']} ***
----------------------------------------------------------------------
Traceback (most recent call last):
  File "/home/elithomas/Documents/CPSC223P/CPSC223P-Lab7/test.py", line 79, in test_list_int
    r = contacts.delete_contact(id = '7145551111')
AttributeError: 'Contacts' object has no attribute 'delete_contact'

======================================================================
ERROR: test_list_int (__main__.Test06_DeleteContact)
*** Test06 *** GIVEN: filename t99.dat = {'7145551111': ['Steve', 'Jobs'], '5625553333': ['Bill', 'Gates']} AND contacts = Contacts(filename='t99.dat') *** FUNCTION CALL: r = contacts.delete_contact(id = '7145551111') *** EXPECT: r = 'error' ***
----------------------------------------------------------------------
Traceback (most recent call last):
  File "/home/elithomas/Documents/CPSC223P/CPSC223P-Lab7/test.py", line 95, in test_list_int
    r = contacts.delete_contact(id = '7145559999')
AttributeError: 'Contacts' object has no attribute 'delete_contact'

----------------------------------------------------------------------
Ran 6 tests in 0.001s

FAILED (errors=4)
